[2025-03-08T20:17:40.689+0000] {taskinstance.py:1087} INFO - Dependencies all met for <TaskInstance: test_dag.fail_task manual__2025-03-08T19:51:24.118312+00:00 [queued]>
[2025-03-08T20:17:40.701+0000] {taskinstance.py:1087} INFO - Dependencies all met for <TaskInstance: test_dag.fail_task manual__2025-03-08T19:51:24.118312+00:00 [queued]>
[2025-03-08T20:17:40.701+0000] {taskinstance.py:1283} INFO - 
--------------------------------------------------------------------------------
[2025-03-08T20:17:40.702+0000] {taskinstance.py:1284} INFO - Starting attempt 8 of 8
[2025-03-08T20:17:40.702+0000] {taskinstance.py:1285} INFO - 
--------------------------------------------------------------------------------
[2025-03-08T20:17:40.718+0000] {taskinstance.py:1304} INFO - Executing <Task(BashOperator): fail_task> on 2025-03-08 19:51:24.118312+00:00
[2025-03-08T20:17:40.723+0000] {standard_task_runner.py:55} INFO - Started process 68 to run task
[2025-03-08T20:17:40.727+0000] {standard_task_runner.py:82} INFO - Running: ['***', 'tasks', 'run', 'test_dag', 'fail_task', 'manual__2025-03-08T19:51:24.118312+00:00', '--job-id', '67', '--raw', '--subdir', 'DAGS_FOLDER/__pycache__/test_dag_ai.py', '--cfg-path', '/tmp/tmp5l1u4eau']
[2025-03-08T20:17:40.727+0000] {standard_task_runner.py:83} INFO - Job 67: Subtask fail_task
[2025-03-08T20:17:40.740+0000] {warnings.py:110} WARNING - /home/***/.local/lib/python3.7/site-packages/***/settings.py:249: DeprecationWarning: The sql_alchemy_conn option in [core] has been moved to the sql_alchemy_conn option in [database] - the old setting has been used, but please update your config.
  SQL_ALCHEMY_CONN = conf.get("database", "SQL_ALCHEMY_CONN")

[2025-03-08T20:17:40.799+0000] {task_command.py:389} INFO - Running <TaskInstance: test_dag.fail_task manual__2025-03-08T19:51:24.118312+00:00 [running]> on host d781a364bdf5
[2025-03-08T20:17:40.867+0000] {taskinstance.py:1513} INFO - Exporting the following env vars:
AIRFLOW_CTX_DAG_OWNER=***
AIRFLOW_CTX_DAG_ID=test_dag
AIRFLOW_CTX_TASK_ID=fail_task
AIRFLOW_CTX_EXECUTION_DATE=2025-03-08T19:51:24.118312+00:00
AIRFLOW_CTX_TRY_NUMBER=8
AIRFLOW_CTX_DAG_RUN_ID=manual__2025-03-08T19:51:24.118312+00:00
[2025-03-08T20:17:40.869+0000] {subprocess.py:63} INFO - Tmp dir root location: 
 /tmp
[2025-03-08T20:17:40.870+0000] {subprocess.py:75} INFO - Running command: ['/bin/bash', '-c', 'exit 1']
[2025-03-08T20:17:40.881+0000] {subprocess.py:86} INFO - Output:
[2025-03-08T20:17:40.925+0000] {subprocess.py:97} INFO - Command exited with return code 1
[2025-03-08T20:17:40.943+0000] {taskinstance.py:1772} ERROR - Task failed with exception
Traceback (most recent call last):
  File "/home/airflow/.local/lib/python3.7/site-packages/airflow/operators/bash.py", line 197, in execute
    f"Bash command failed. The command returned a non-zero exit code {result.exit_code}."
airflow.exceptions.AirflowException: Bash command failed. The command returned a non-zero exit code 1.
[2025-03-08T20:17:40.950+0000] {taskinstance.py:1327} INFO - Marking task as FAILED. dag_id=test_dag, task_id=fail_task, execution_date=20250308T195124, start_date=20250308T201740, end_date=20250308T201740
[2025-03-08T20:17:41.958+0000] {util.py:67} INFO - error_code=insufficient_quota error_message='You exceeded your current quota, please check your plan and billing details. For more information on this error, read the docs: https://platform.openai.com/docs/guides/error-codes/api-errors.' error_param=None error_type=insufficient_quota message='OpenAI API error received' stream_error=False
[2025-03-08T20:17:41.961+0000] {test_dag_ai.py:28} ERROR - LLM analysis failed: You exceeded your current quota, please check your plan and billing details. For more information on this error, read the docs: https://platform.openai.com/docs/guides/error-codes/api-errors.
[2025-03-08T20:17:41.986+0000] {warnings.py:110} WARNING - /home/***/.local/lib/python3.7/site-packages/***/utils/email.py:120: RemovedInAirflow3Warning: Fetching SMTP credentials from configuration variables will be deprecated in a future release. Please set credentials using a connection instead.
  send_mime_email(e_from=mail_from, e_to=recipients, mime_msg=msg, conn_id=conn_id, dryrun=dryrun)

[2025-03-08T20:17:41.987+0000] {email.py:229} INFO - Email alerting: attempt 1
[2025-03-08T20:17:43.693+0000] {email.py:241} INFO - Sent an alert email to ['monishassan1997@gmail.com']
[2025-03-08T20:17:45.350+0000] {standard_task_runner.py:105} ERROR - Failed to execute job 67 for task fail_task (Bash command failed. The command returned a non-zero exit code 1.; 68)
[2025-03-08T20:17:45.377+0000] {local_task_job.py:159} INFO - Task exited with return code 1
[2025-03-08T20:17:45.430+0000] {taskinstance.py:2582} INFO - 0 downstream tasks scheduled from follow-on schedule check
