[2025-03-08T20:41:20.392+0000] {taskinstance.py:1087} INFO - Dependencies all met for <TaskInstance: test_dag.fail_task manual__2025-03-08T19:51:24.118312+00:00 [queued]>
[2025-03-08T20:41:20.401+0000] {taskinstance.py:1087} INFO - Dependencies all met for <TaskInstance: test_dag.fail_task manual__2025-03-08T19:51:24.118312+00:00 [queued]>
[2025-03-08T20:41:20.401+0000] {taskinstance.py:1283} INFO - 
--------------------------------------------------------------------------------
[2025-03-08T20:41:20.401+0000] {taskinstance.py:1284} INFO - Starting attempt 14 of 14
[2025-03-08T20:41:20.401+0000] {taskinstance.py:1285} INFO - 
--------------------------------------------------------------------------------
[2025-03-08T20:41:20.412+0000] {taskinstance.py:1304} INFO - Executing <Task(BashOperator): fail_task> on 2025-03-08 19:51:24.118312+00:00
[2025-03-08T20:41:20.417+0000] {standard_task_runner.py:55} INFO - Started process 104 to run task
[2025-03-08T20:41:20.421+0000] {standard_task_runner.py:82} INFO - Running: ['***', 'tasks', 'run', 'test_dag', 'fail_task', 'manual__2025-03-08T19:51:24.118312+00:00', '--job-id', '79', '--raw', '--subdir', 'DAGS_FOLDER/__pycache__/test_dag_ai.py', '--cfg-path', '/tmp/tmpn7b8e5sv']
[2025-03-08T20:41:20.422+0000] {standard_task_runner.py:83} INFO - Job 79: Subtask fail_task
[2025-03-08T20:41:20.434+0000] {warnings.py:110} WARNING - /home/***/.local/lib/python3.7/site-packages/***/settings.py:249: DeprecationWarning: The sql_alchemy_conn option in [core] has been moved to the sql_alchemy_conn option in [database] - the old setting has been used, but please update your config.
  SQL_ALCHEMY_CONN = conf.get("database", "SQL_ALCHEMY_CONN")

[2025-03-08T20:41:20.478+0000] {task_command.py:389} INFO - Running <TaskInstance: test_dag.fail_task manual__2025-03-08T19:51:24.118312+00:00 [running]> on host d781a364bdf5
[2025-03-08T20:41:20.528+0000] {taskinstance.py:1513} INFO - Exporting the following env vars:
AIRFLOW_CTX_DAG_OWNER=***
AIRFLOW_CTX_DAG_ID=test_dag
AIRFLOW_CTX_TASK_ID=fail_task
AIRFLOW_CTX_EXECUTION_DATE=2025-03-08T19:51:24.118312+00:00
AIRFLOW_CTX_TRY_NUMBER=14
AIRFLOW_CTX_DAG_RUN_ID=manual__2025-03-08T19:51:24.118312+00:00
[2025-03-08T20:41:20.530+0000] {subprocess.py:63} INFO - Tmp dir root location: 
 /tmp
[2025-03-08T20:41:20.530+0000] {subprocess.py:75} INFO - Running command: ['/bin/bash', '-c', 'exit 1']
[2025-03-08T20:41:20.538+0000] {subprocess.py:86} INFO - Output:
[2025-03-08T20:41:20.565+0000] {subprocess.py:97} INFO - Command exited with return code 1
[2025-03-08T20:41:20.574+0000] {taskinstance.py:1772} ERROR - Task failed with exception
Traceback (most recent call last):
  File "/home/airflow/.local/lib/python3.7/site-packages/airflow/operators/bash.py", line 197, in execute
    f"Bash command failed. The command returned a non-zero exit code {result.exit_code}."
airflow.exceptions.AirflowException: Bash command failed. The command returned a non-zero exit code 1.
[2025-03-08T20:41:20.577+0000] {taskinstance.py:1327} INFO - Marking task as FAILED. dag_id=test_dag, task_id=fail_task, execution_date=20250308T195124, start_date=20250308T204120, end_date=20250308T204120
[2025-03-08T20:41:22.509+0000] {test_dag_ai.py:30} INFO - LLM analysis completed successfully.
[2025-03-08T20:41:22.511+0000] {test_dag_ai.py:42} ERROR - LLM analysis failed: text
[2025-03-08T20:41:22.525+0000] {warnings.py:110} WARNING - /home/***/.local/lib/python3.7/site-packages/***/utils/email.py:120: RemovedInAirflow3Warning: Fetching SMTP credentials from configuration variables will be deprecated in a future release. Please set credentials using a connection instead.
  send_mime_email(e_from=mail_from, e_to=recipients, mime_msg=msg, conn_id=conn_id, dryrun=dryrun)

[2025-03-08T20:41:22.525+0000] {email.py:229} INFO - Email alerting: attempt 1
[2025-03-08T20:41:24.714+0000] {email.py:241} INFO - Sent an alert email to ['monishassan1997@gmail.com']
[2025-03-08T20:41:26.350+0000] {standard_task_runner.py:105} ERROR - Failed to execute job 79 for task fail_task (Bash command failed. The command returned a non-zero exit code 1.; 104)
[2025-03-08T20:41:26.392+0000] {local_task_job.py:159} INFO - Task exited with return code 1
[2025-03-08T20:41:26.452+0000] {taskinstance.py:2582} INFO - 0 downstream tasks scheduled from follow-on schedule check
