[2025-03-08T19:56:32.145+0000] {taskinstance.py:1087} INFO - Dependencies all met for <TaskInstance: test_dag.fail_task manual__2025-03-08T19:51:24.118312+00:00 [queued]>
[2025-03-08T19:56:32.153+0000] {taskinstance.py:1087} INFO - Dependencies all met for <TaskInstance: test_dag.fail_task manual__2025-03-08T19:51:24.118312+00:00 [queued]>
[2025-03-08T19:56:32.153+0000] {taskinstance.py:1283} INFO - 
--------------------------------------------------------------------------------
[2025-03-08T19:56:32.153+0000] {taskinstance.py:1284} INFO - Starting attempt 2 of 2
[2025-03-08T19:56:32.154+0000] {taskinstance.py:1285} INFO - 
--------------------------------------------------------------------------------
[2025-03-08T19:56:32.165+0000] {taskinstance.py:1304} INFO - Executing <Task(BashOperator): fail_task> on 2025-03-08 19:51:24.118312+00:00
[2025-03-08T19:56:32.169+0000] {standard_task_runner.py:55} INFO - Started process 110 to run task
[2025-03-08T19:56:32.175+0000] {standard_task_runner.py:82} INFO - Running: ['***', 'tasks', 'run', 'test_dag', 'fail_task', 'manual__2025-03-08T19:51:24.118312+00:00', '--job-id', '55', '--raw', '--subdir', 'DAGS_FOLDER/__pycache__/test_dag_ai.py', '--cfg-path', '/tmp/tmpyor6kw2w']
[2025-03-08T19:56:32.176+0000] {standard_task_runner.py:83} INFO - Job 55: Subtask fail_task
[2025-03-08T19:56:32.186+0000] {warnings.py:110} WARNING - /home/***/.local/lib/python3.7/site-packages/***/settings.py:249: DeprecationWarning: The sql_alchemy_conn option in [core] has been moved to the sql_alchemy_conn option in [database] - the old setting has been used, but please update your config.
  SQL_ALCHEMY_CONN = conf.get("database", "SQL_ALCHEMY_CONN")

[2025-03-08T19:56:32.232+0000] {task_command.py:389} INFO - Running <TaskInstance: test_dag.fail_task manual__2025-03-08T19:51:24.118312+00:00 [running]> on host 1d5c1ffaa84f
[2025-03-08T19:56:32.287+0000] {taskinstance.py:1513} INFO - Exporting the following env vars:
AIRFLOW_CTX_DAG_OWNER=***
AIRFLOW_CTX_DAG_ID=test_dag
AIRFLOW_CTX_TASK_ID=fail_task
AIRFLOW_CTX_EXECUTION_DATE=2025-03-08T19:51:24.118312+00:00
AIRFLOW_CTX_TRY_NUMBER=2
AIRFLOW_CTX_DAG_RUN_ID=manual__2025-03-08T19:51:24.118312+00:00
[2025-03-08T19:56:32.288+0000] {subprocess.py:63} INFO - Tmp dir root location: 
 /tmp
[2025-03-08T19:56:32.289+0000] {subprocess.py:75} INFO - Running command: ['/bin/bash', '-c', 'exit 1']
[2025-03-08T19:56:32.299+0000] {subprocess.py:86} INFO - Output:
[2025-03-08T19:56:32.325+0000] {subprocess.py:97} INFO - Command exited with return code 1
[2025-03-08T19:56:32.334+0000] {taskinstance.py:1772} ERROR - Task failed with exception
Traceback (most recent call last):
  File "/home/airflow/.local/lib/python3.7/site-packages/airflow/operators/bash.py", line 197, in execute
    f"Bash command failed. The command returned a non-zero exit code {result.exit_code}."
airflow.exceptions.AirflowException: Bash command failed. The command returned a non-zero exit code 1.
[2025-03-08T19:56:32.337+0000] {taskinstance.py:1327} INFO - Marking task as FAILED. dag_id=test_dag, task_id=fail_task, execution_date=20250308T195124, start_date=20250308T195632, end_date=20250308T195632
[2025-03-08T19:56:32.338+0000] {test_dag_ai.py:82} ERROR - Error reading log file: [Errno 2] No such file or directory: '/opt/***/logs/dag_id=test_dag/run_id=manual__2025-03-08T19_51_24_118312+00_00/task_id=fail_task/attempt=2.log'
[2025-03-08T19:56:32.343+0000] {warnings.py:110} WARNING - /home/***/.local/lib/python3.7/site-packages/***/utils/email.py:120: RemovedInAirflow3Warning: Fetching SMTP credentials from configuration variables will be deprecated in a future release. Please set credentials using a connection instead.
  send_mime_email(e_from=mail_from, e_to=recipients, mime_msg=msg, conn_id=conn_id, dryrun=dryrun)

[2025-03-08T19:56:32.343+0000] {email.py:229} INFO - Email alerting: attempt 1
[2025-03-08T19:56:35.021+0000] {email.py:241} INFO - Sent an alert email to ['monishassan1997@gmail.com']
[2025-03-08T19:56:36.635+0000] {standard_task_runner.py:105} ERROR - Failed to execute job 55 for task fail_task (Bash command failed. The command returned a non-zero exit code 1.; 110)
[2025-03-08T19:56:36.677+0000] {local_task_job.py:159} INFO - Task exited with return code 1
[2025-03-08T19:56:36.697+0000] {taskinstance.py:2582} INFO - 0 downstream tasks scheduled from follow-on schedule check
