[2025-03-08T19:49:26.989+0000] {taskinstance.py:1087} INFO - Dependencies all met for <TaskInstance: test_dag.fail_task manual__2025-03-08T19:35:53.506228+00:00 [queued]>
[2025-03-08T19:49:26.997+0000] {taskinstance.py:1087} INFO - Dependencies all met for <TaskInstance: test_dag.fail_task manual__2025-03-08T19:35:53.506228+00:00 [queued]>
[2025-03-08T19:49:26.998+0000] {taskinstance.py:1283} INFO - 
--------------------------------------------------------------------------------
[2025-03-08T19:49:26.998+0000] {taskinstance.py:1284} INFO - Starting attempt 4 of 5
[2025-03-08T19:49:26.998+0000] {taskinstance.py:1285} INFO - 
--------------------------------------------------------------------------------
[2025-03-08T19:49:27.008+0000] {taskinstance.py:1304} INFO - Executing <Task(BashOperator): fail_task> on 2025-03-08 19:35:53.506228+00:00
[2025-03-08T19:49:27.013+0000] {standard_task_runner.py:55} INFO - Started process 101 to run task
[2025-03-08T19:49:27.017+0000] {standard_task_runner.py:82} INFO - Running: ['***', 'tasks', 'run', 'test_dag', 'fail_task', 'manual__2025-03-08T19:35:53.506228+00:00', '--job-id', '52', '--raw', '--subdir', 'DAGS_FOLDER/__pycache__/test_dag_ai.py', '--cfg-path', '/tmp/tmp11kdjdi1']
[2025-03-08T19:49:27.017+0000] {standard_task_runner.py:83} INFO - Job 52: Subtask fail_task
[2025-03-08T19:49:27.026+0000] {warnings.py:110} WARNING - /home/***/.local/lib/python3.7/site-packages/***/settings.py:249: DeprecationWarning: The sql_alchemy_conn option in [core] has been moved to the sql_alchemy_conn option in [database] - the old setting has been used, but please update your config.
  SQL_ALCHEMY_CONN = conf.get("database", "SQL_ALCHEMY_CONN")

[2025-03-08T19:49:27.064+0000] {task_command.py:389} INFO - Running <TaskInstance: test_dag.fail_task manual__2025-03-08T19:35:53.506228+00:00 [running]> on host 1d5c1ffaa84f
[2025-03-08T19:49:27.115+0000] {taskinstance.py:1513} INFO - Exporting the following env vars:
AIRFLOW_CTX_DAG_OWNER=***
AIRFLOW_CTX_DAG_ID=test_dag
AIRFLOW_CTX_TASK_ID=fail_task
AIRFLOW_CTX_EXECUTION_DATE=2025-03-08T19:35:53.506228+00:00
AIRFLOW_CTX_TRY_NUMBER=4
AIRFLOW_CTX_DAG_RUN_ID=manual__2025-03-08T19:35:53.506228+00:00
[2025-03-08T19:49:27.116+0000] {subprocess.py:63} INFO - Tmp dir root location: 
 /tmp
[2025-03-08T19:49:27.117+0000] {subprocess.py:75} INFO - Running command: ['/bin/bash', '-c', 'exit 1']
[2025-03-08T19:49:27.124+0000] {subprocess.py:86} INFO - Output:
[2025-03-08T19:49:27.148+0000] {subprocess.py:97} INFO - Command exited with return code 1
[2025-03-08T19:49:27.156+0000] {taskinstance.py:1772} ERROR - Task failed with exception
Traceback (most recent call last):
  File "/home/airflow/.local/lib/python3.7/site-packages/airflow/operators/bash.py", line 197, in execute
    f"Bash command failed. The command returned a non-zero exit code {result.exit_code}."
airflow.exceptions.AirflowException: Bash command failed. The command returned a non-zero exit code 1.
[2025-03-08T19:49:27.160+0000] {taskinstance.py:1327} INFO - Marking task as UP_FOR_RETRY. dag_id=test_dag, task_id=fail_task, execution_date=20250308T193553, start_date=20250308T194926, end_date=20250308T194927
[2025-03-08T19:49:27.169+0000] {standard_task_runner.py:105} ERROR - Failed to execute job 52 for task fail_task (Bash command failed. The command returned a non-zero exit code 1.; 101)
[2025-03-08T19:49:27.195+0000] {local_task_job.py:159} INFO - Task exited with return code 1
[2025-03-08T19:49:27.217+0000] {taskinstance.py:2582} INFO - 0 downstream tasks scheduled from follow-on schedule check
