[2025-03-08T19:41:00.878+0000] {taskinstance.py:1087} INFO - Dependencies all met for <TaskInstance: test_dag.fail_task manual__2025-03-08T19:35:53.506228+00:00 [queued]>
[2025-03-08T19:41:00.885+0000] {taskinstance.py:1087} INFO - Dependencies all met for <TaskInstance: test_dag.fail_task manual__2025-03-08T19:35:53.506228+00:00 [queued]>
[2025-03-08T19:41:00.885+0000] {taskinstance.py:1283} INFO - 
--------------------------------------------------------------------------------
[2025-03-08T19:41:00.886+0000] {taskinstance.py:1284} INFO - Starting attempt 3 of 4
[2025-03-08T19:41:00.886+0000] {taskinstance.py:1285} INFO - 
--------------------------------------------------------------------------------
[2025-03-08T19:41:00.896+0000] {taskinstance.py:1304} INFO - Executing <Task(BashOperator): fail_task> on 2025-03-08 19:35:53.506228+00:00
[2025-03-08T19:41:00.899+0000] {standard_task_runner.py:55} INFO - Started process 95 to run task
[2025-03-08T19:41:00.903+0000] {standard_task_runner.py:82} INFO - Running: ['***', 'tasks', 'run', 'test_dag', 'fail_task', 'manual__2025-03-08T19:35:53.506228+00:00', '--job-id', '50', '--raw', '--subdir', 'DAGS_FOLDER/__pycache__/test_dag_ai.py', '--cfg-path', '/tmp/tmpur2tb276']
[2025-03-08T19:41:00.904+0000] {standard_task_runner.py:83} INFO - Job 50: Subtask fail_task
[2025-03-08T19:41:00.912+0000] {warnings.py:110} WARNING - /home/***/.local/lib/python3.7/site-packages/***/settings.py:249: DeprecationWarning: The sql_alchemy_conn option in [core] has been moved to the sql_alchemy_conn option in [database] - the old setting has been used, but please update your config.
  SQL_ALCHEMY_CONN = conf.get("database", "SQL_ALCHEMY_CONN")

[2025-03-08T19:41:00.948+0000] {task_command.py:389} INFO - Running <TaskInstance: test_dag.fail_task manual__2025-03-08T19:35:53.506228+00:00 [running]> on host 1d5c1ffaa84f
[2025-03-08T19:41:00.995+0000] {taskinstance.py:1513} INFO - Exporting the following env vars:
AIRFLOW_CTX_DAG_OWNER=***
AIRFLOW_CTX_DAG_ID=test_dag
AIRFLOW_CTX_TASK_ID=fail_task
AIRFLOW_CTX_EXECUTION_DATE=2025-03-08T19:35:53.506228+00:00
AIRFLOW_CTX_TRY_NUMBER=3
AIRFLOW_CTX_DAG_RUN_ID=manual__2025-03-08T19:35:53.506228+00:00
[2025-03-08T19:41:00.996+0000] {subprocess.py:63} INFO - Tmp dir root location: 
 /tmp
[2025-03-08T19:41:00.997+0000] {subprocess.py:75} INFO - Running command: ['/bin/bash', '-c', 'exit 1']
[2025-03-08T19:41:01.007+0000] {subprocess.py:86} INFO - Output:
[2025-03-08T19:41:01.038+0000] {subprocess.py:97} INFO - Command exited with return code 1
[2025-03-08T19:41:01.050+0000] {taskinstance.py:1772} ERROR - Task failed with exception
Traceback (most recent call last):
  File "/home/airflow/.local/lib/python3.7/site-packages/airflow/operators/bash.py", line 197, in execute
    f"Bash command failed. The command returned a non-zero exit code {result.exit_code}."
airflow.exceptions.AirflowException: Bash command failed. The command returned a non-zero exit code 1.
[2025-03-08T19:41:01.054+0000] {taskinstance.py:1327} INFO - Marking task as UP_FOR_RETRY. dag_id=test_dag, task_id=fail_task, execution_date=20250308T193553, start_date=20250308T194100, end_date=20250308T194101
[2025-03-08T19:41:01.066+0000] {standard_task_runner.py:105} ERROR - Failed to execute job 50 for task fail_task (Bash command failed. The command returned a non-zero exit code 1.; 95)
[2025-03-08T19:41:01.082+0000] {local_task_job.py:159} INFO - Task exited with return code 1
[2025-03-08T19:41:01.118+0000] {taskinstance.py:2582} INFO - 0 downstream tasks scheduled from follow-on schedule check
