[2025-03-08T19:39:55.271+0000] {taskinstance.py:1087} INFO - Dependencies all met for <TaskInstance: test_dag.fail_task manual__2025-03-08T19:35:53.506228+00:00 [queued]>
[2025-03-08T19:39:55.278+0000] {taskinstance.py:1087} INFO - Dependencies all met for <TaskInstance: test_dag.fail_task manual__2025-03-08T19:35:53.506228+00:00 [queued]>
[2025-03-08T19:39:55.278+0000] {taskinstance.py:1283} INFO - 
--------------------------------------------------------------------------------
[2025-03-08T19:39:55.278+0000] {taskinstance.py:1284} INFO - Starting attempt 2 of 3
[2025-03-08T19:39:55.278+0000] {taskinstance.py:1285} INFO - 
--------------------------------------------------------------------------------
[2025-03-08T19:39:55.288+0000] {taskinstance.py:1304} INFO - Executing <Task(BashOperator): fail_task> on 2025-03-08 19:35:53.506228+00:00
[2025-03-08T19:39:55.291+0000] {standard_task_runner.py:55} INFO - Started process 89 to run task
[2025-03-08T19:39:55.294+0000] {standard_task_runner.py:82} INFO - Running: ['***', 'tasks', 'run', 'test_dag', 'fail_task', 'manual__2025-03-08T19:35:53.506228+00:00', '--job-id', '48', '--raw', '--subdir', 'DAGS_FOLDER/__pycache__/test_dag_ai.py', '--cfg-path', '/tmp/tmp46aq5d0r']
[2025-03-08T19:39:55.295+0000] {standard_task_runner.py:83} INFO - Job 48: Subtask fail_task
[2025-03-08T19:39:55.308+0000] {warnings.py:110} WARNING - /home/***/.local/lib/python3.7/site-packages/***/settings.py:249: DeprecationWarning: The sql_alchemy_conn option in [core] has been moved to the sql_alchemy_conn option in [database] - the old setting has been used, but please update your config.
  SQL_ALCHEMY_CONN = conf.get("database", "SQL_ALCHEMY_CONN")

[2025-03-08T19:39:55.344+0000] {task_command.py:389} INFO - Running <TaskInstance: test_dag.fail_task manual__2025-03-08T19:35:53.506228+00:00 [running]> on host 1d5c1ffaa84f
[2025-03-08T19:39:55.390+0000] {taskinstance.py:1513} INFO - Exporting the following env vars:
AIRFLOW_CTX_DAG_OWNER=***
AIRFLOW_CTX_DAG_ID=test_dag
AIRFLOW_CTX_TASK_ID=fail_task
AIRFLOW_CTX_EXECUTION_DATE=2025-03-08T19:35:53.506228+00:00
AIRFLOW_CTX_TRY_NUMBER=2
AIRFLOW_CTX_DAG_RUN_ID=manual__2025-03-08T19:35:53.506228+00:00
[2025-03-08T19:39:55.391+0000] {subprocess.py:63} INFO - Tmp dir root location: 
 /tmp
[2025-03-08T19:39:55.392+0000] {subprocess.py:75} INFO - Running command: ['/bin/bash', '-c', 'exit 1']
[2025-03-08T19:39:55.398+0000] {subprocess.py:86} INFO - Output:
[2025-03-08T19:39:55.422+0000] {subprocess.py:97} INFO - Command exited with return code 1
[2025-03-08T19:39:55.432+0000] {taskinstance.py:1772} ERROR - Task failed with exception
Traceback (most recent call last):
  File "/home/airflow/.local/lib/python3.7/site-packages/airflow/operators/bash.py", line 197, in execute
    f"Bash command failed. The command returned a non-zero exit code {result.exit_code}."
airflow.exceptions.AirflowException: Bash command failed. The command returned a non-zero exit code 1.
[2025-03-08T19:39:55.435+0000] {taskinstance.py:1327} INFO - Marking task as UP_FOR_RETRY. dag_id=test_dag, task_id=fail_task, execution_date=20250308T193553, start_date=20250308T193955, end_date=20250308T193955
[2025-03-08T19:39:55.444+0000] {standard_task_runner.py:105} ERROR - Failed to execute job 48 for task fail_task (Bash command failed. The command returned a non-zero exit code 1.; 89)
[2025-03-08T19:39:55.476+0000] {local_task_job.py:159} INFO - Task exited with return code 1
[2025-03-08T19:39:55.498+0000] {taskinstance.py:2582} INFO - 0 downstream tasks scheduled from follow-on schedule check
